<?xml version="1.0"?>
<!--
  FANUC CR-7iA URDF
  Generated from: ros-industrial/fanuc fanuc_cr7ia_support/urdf/cr7ia_macro.xacro
  Source: https://github.com/ros-industrial/fanuc
  License: BSD 3-Clause
  Mesh paths resolved to package://fanuc_cr7ia — maps to /models/fanuc/cr7ia in the app.
-->
<robot name="fanuc_cr7ia">

  <material name="fanuc_green">
    <color rgba="0.0 0.6 0.2 1.0"/>
  </material>
  <material name="fanuc_gray">
    <color rgba="0.28 0.28 0.28 1.0"/>
  </material>

  <!-- LINKS -->

  <link name="base_link">
    <visual>
      <origin xyz="0 0 0" rpy="0 0 0"/>
      <geometry>
        <mesh filename="package://fanuc_cr7ia/meshes/visual/base_link.stl"/>
      </geometry>
      <material name="fanuc_gray"/>
    </visual>
  </link>

  <link name="link_1">
    <visual>
      <origin xyz="0 0 0" rpy="0 0 0"/>
      <geometry>
        <mesh filename="package://fanuc_cr7ia/meshes/visual/link_1.stl"/>
      </geometry>
      <material name="fanuc_green"/>
    </visual>
  </link>

  <link name="link_2">
    <visual>
      <origin xyz="0 0 0" rpy="0 0 0"/>
      <geometry>
        <mesh filename="package://fanuc_cr7ia/meshes/visual/link_2.stl"/>
      </geometry>
      <material name="fanuc_green"/>
    </visual>
  </link>

  <link name="link_3">
    <visual>
      <origin xyz="0 0 0" rpy="0 0 0"/>
      <geometry>
        <mesh filename="package://fanuc_cr7ia/meshes/visual/link_3.stl"/>
      </geometry>
      <material name="fanuc_green"/>
    </visual>
  </link>

  <link name="link_4">
    <visual>
      <origin xyz="0 0 0" rpy="0 0 0"/>
      <geometry>
        <mesh filename="package://fanuc_cr7ia/meshes/visual/link_4.stl"/>
      </geometry>
      <material name="fanuc_green"/>
    </visual>
  </link>

  <link name="link_5">
    <visual>
      <origin xyz="0 0 0" rpy="0 0 0"/>
      <geometry>
        <mesh filename="package://fanuc_cr7ia/meshes/visual/link_5.stl"/>
      </geometry>
      <material name="fanuc_green"/>
    </visual>
  </link>

  <link name="link_6">
    <visual>
      <origin xyz="0 0 0" rpy="0 0 0"/>
      <geometry>
        <mesh filename="package://fanuc_cr7ia/meshes/visual/link_6.stl"/>
      </geometry>
      <material name="fanuc_gray"/>
    </visual>
  </link>

  <!-- JOINTS (transforms from xacro macro, radians expanded) -->

  <!-- base_link → link_1: 457mm rise -->
  <joint name="joint_1" type="revolute">
    <origin xyz="0 0 0.457" rpy="0 0 0"/>
    <parent link="base_link"/>
    <child link="link_1"/>
    <axis xyz="0 0 1"/>
    <limit effort="0" lower="-2.9671" upper="2.9671" velocity="7.8539"/>
  </joint>

  <!-- link_1 → link_2: 50mm offset -->
  <joint name="joint_2" type="revolute">
    <origin xyz="0.05 0 0" rpy="0 0 0"/>
    <parent link="link_1"/>
    <child link="link_2"/>
    <axis xyz="0 1 0"/>
    <limit effort="0" lower="-1.1519" upper="1.7453" velocity="6.6322"/>
  </joint>

  <!-- link_2 → link_3: 330mm rise -->
  <joint name="joint_3" type="revolute">
    <origin xyz="0 0 0.330" rpy="0 0 0"/>
    <parent link="link_2"/>
    <child link="link_3"/>
    <axis xyz="0 -1 0"/>
    <limit effort="0" lower="-2.2621" upper="4.2586" velocity="9.0757"/>
  </joint>

  <!-- link_3 → link_4: 35mm rise -->
  <joint name="joint_4" type="revolute">
    <origin xyz="0 0 0.035" rpy="0 0 0"/>
    <parent link="link_3"/>
    <child link="link_4"/>
    <axis xyz="-1 0 0"/>
    <limit effort="0" lower="-3.3161" upper="3.3161" velocity="9.5993"/>
  </joint>

  <!-- link_4 → link_5: 335mm reach -->
  <joint name="joint_5" type="revolute">
    <origin xyz="0.335 0 0" rpy="0 0 0"/>
    <parent link="link_4"/>
    <child link="link_5"/>
    <axis xyz="0 -1 0"/>
    <limit effort="0" lower="-2.0944" upper="2.0944" velocity="9.5120"/>
  </joint>

  <!-- link_5 → link_6: 80mm reach -->
  <joint name="joint_6" type="revolute">
    <origin xyz="0.080 0 0" rpy="0 0 0"/>
    <parent link="link_5"/>
    <child link="link_6"/>
    <axis xyz="-1 0 0"/>
    <limit effort="0" lower="-6.2832" upper="6.2832" velocity="17.4532"/>
  </joint>

</robot>
