<?xml version="1.0"?>
<!--
  FANUC M-10iA URDF
  Generated from: ros-industrial/fanuc fanuc_m10ia_support/urdf/m10ia_macro.xacro
  Source: https://github.com/ros-industrial/fanuc
  License: BSD 3-Clause
  Mesh paths resolved to package://fanuc_m10ia — maps to /models/fanuc/m10ia in the app.
-->
<robot name="fanuc_m10ia">

  <material name="fanuc_yellow">
    <color rgba="1.0 0.78 0.0 1.0"/>
  </material>
  <material name="fanuc_gray">
    <color rgba="0.28 0.28 0.28 1.0"/>
  </material>
  <material name="fanuc_black">
    <color rgba="0.1 0.1 0.1 1.0"/>
  </material>

  <!-- LINKS -->

  <link name="base_link">
    <visual>
      <origin xyz="0 0 0" rpy="0 0 0"/>
      <geometry>
        <mesh filename="package://fanuc_m10ia/meshes/visual/base_link.stl"/>
      </geometry>
      <material name="fanuc_gray"/>
    </visual>
  </link>

  <link name="link_1">
    <visual>
      <origin xyz="0 0 0" rpy="0 0 0"/>
      <geometry>
        <mesh filename="package://fanuc_m10ia/meshes/visual/link_1.stl"/>
      </geometry>
      <material name="fanuc_yellow"/>
    </visual>
  </link>

  <link name="link_2">
    <visual>
      <origin xyz="0 0 0" rpy="0 0 0"/>
      <geometry>
        <mesh filename="package://fanuc_m10ia/meshes/visual/link_2.stl"/>
      </geometry>
      <material name="fanuc_yellow"/>
    </visual>
  </link>

  <link name="link_3">
    <visual>
      <origin xyz="0 0 0" rpy="0 0 0"/>
      <geometry>
        <mesh filename="package://fanuc_m10ia/meshes/visual/link_3.stl"/>
      </geometry>
      <material name="fanuc_yellow"/>
    </visual>
  </link>

  <link name="link_4">
    <visual>
      <origin xyz="0 0 0" rpy="0 0 0"/>
      <geometry>
        <mesh filename="package://fanuc_m10ia/meshes/visual/link_4.stl"/>
      </geometry>
      <material name="fanuc_yellow"/>
    </visual>
  </link>

  <link name="link_5">
    <visual>
      <origin xyz="0 0 0" rpy="0 0 0"/>
      <geometry>
        <mesh filename="package://fanuc_m10ia/meshes/visual/link_5.stl"/>
      </geometry>
      <material name="fanuc_yellow"/>
    </visual>
  </link>

  <link name="link_6">
    <visual>
      <origin xyz="0 0 0" rpy="0 0 0"/>
      <geometry>
        <mesh filename="package://fanuc_m10ia/meshes/visual/link_6.stl"/>
      </geometry>
      <material name="fanuc_black"/>
    </visual>
  </link>

  <!-- JOINTS (transforms from xacro macro, radians expanded) -->

  <!-- base_link → link_1: 450mm rise -->
  <joint name="joint_1" type="revolute">
    <origin xyz="0 0 0.450" rpy="0 0 0"/>
    <parent link="base_link"/>
    <child link="link_1"/>
    <axis xyz="0 0 1"/>
    <limit effort="0" lower="-3.14" upper="3.14" velocity="3.67"/>
  </joint>

  <!-- link_1 → link_2: 150mm offset -->
  <joint name="joint_2" type="revolute">
    <origin xyz="0.150 0 0" rpy="0 0 0"/>
    <parent link="link_1"/>
    <child link="link_2"/>
    <axis xyz="0 1 0"/>
    <limit effort="0" lower="-1.57" upper="2.79" velocity="3.32"/>
  </joint>

  <!-- link_2 → link_3: 600mm rise -->
  <joint name="joint_3" type="revolute">
    <origin xyz="0 0 0.600" rpy="0 0 0"/>
    <parent link="link_2"/>
    <child link="link_3"/>
    <axis xyz="0 -1 0"/>
    <limit effort="0" lower="-3.14" upper="4.61" velocity="3.67"/>
  </joint>

  <!-- link_3 → link_4: 200mm rise -->
  <joint name="joint_4" type="revolute">
    <origin xyz="0 0 0.200" rpy="0 0 0"/>
    <parent link="link_3"/>
    <child link="link_4"/>
    <axis xyz="-1 0 0"/>
    <limit effort="0" lower="-3.31" upper="3.31" velocity="6.98"/>
  </joint>

  <!-- link_4 → link_5: 640mm reach -->
  <joint name="joint_5" type="revolute">
    <origin xyz="0.640 0 0" rpy="0 0 0"/>
    <parent link="link_4"/>
    <child link="link_5"/>
    <axis xyz="0 -1 0"/>
    <limit effort="0" lower="-3.31" upper="3.31" velocity="6.98"/>
  </joint>

  <!-- link_5 → link_6: 100mm reach -->
  <joint name="joint_6" type="revolute">
    <origin xyz="0.100 0 0" rpy="0 0 0"/>
    <parent link="link_5"/>
    <child link="link_6"/>
    <axis xyz="-1 0 0"/>
    <limit effort="0" lower="-6.28" upper="6.28" velocity="10.47"/>
  </joint>

</robot>
