<?xml version="1.0"?>
<!--
  FANUC M-20iA URDF
  Generated from: ros-industrial/fanuc fanuc_m20ia_support/urdf/m20ia_macro.xacro
  Source: https://github.com/ros-industrial/fanuc
  License: BSD 3-Clause
  Mesh paths resolved to package://fanuc_m20ia — maps to /models/fanuc/m20ia in the app.
-->
<robot name="fanuc_m20ia">

  <material name="fanuc_yellow">
    <color rgba="1.0 0.78 0.0 1.0"/>
  </material>
  <material name="fanuc_gray">
    <color rgba="0.28 0.28 0.28 1.0"/>
  </material>
  <material name="fanuc_black">
    <color rgba="0.1 0.1 0.1 1.0"/>
  </material>

  <!-- LINKS -->

  <link name="base_link">
    <visual>
      <origin xyz="0 0 0" rpy="0 0 0"/>
      <geometry>
        <mesh filename="package://fanuc_m20ia/meshes/visual/base_link.stl"/>
      </geometry>
      <material name="fanuc_gray"/>
    </visual>
  </link>

  <link name="link_1">
    <visual>
      <origin xyz="0 0 0" rpy="0 0 0"/>
      <geometry>
        <mesh filename="package://fanuc_m20ia/meshes/visual/link_1.stl"/>
      </geometry>
      <material name="fanuc_yellow"/>
    </visual>
  </link>

  <link name="link_2">
    <visual>
      <origin xyz="0 0 0" rpy="0 0 0"/>
      <geometry>
        <mesh filename="package://fanuc_m20ia/meshes/visual/link_2.stl"/>
      </geometry>
      <material name="fanuc_yellow"/>
    </visual>
  </link>

  <link name="link_3">
    <visual>
      <origin xyz="0 0 0" rpy="0 0 0"/>
      <geometry>
        <mesh filename="package://fanuc_m20ia/meshes/visual/link_3.stl"/>
      </geometry>
      <material name="fanuc_yellow"/>
    </visual>
  </link>

  <link name="link_4">
    <visual>
      <origin xyz="0 0 0" rpy="0 0 0"/>
      <geometry>
        <mesh filename="package://fanuc_m20ia/meshes/visual/link_4.stl"/>
      </geometry>
      <material name="fanuc_yellow"/>
    </visual>
  </link>

  <link name="link_5">
    <visual>
      <origin xyz="0 0 0" rpy="0 0 0"/>
      <geometry>
        <mesh filename="package://fanuc_m20ia/meshes/visual/link_5.stl"/>
      </geometry>
      <material name="fanuc_yellow"/>
    </visual>
  </link>

  <link name="link_6">
    <visual>
      <origin xyz="0 0 0" rpy="0 0 0"/>
      <geometry>
        <mesh filename="package://fanuc_m20ia/meshes/visual/link_6.stl"/>
      </geometry>
      <material name="fanuc_black"/>
    </visual>
  </link>

  <!-- JOINTS (transforms from xacro macro, radians expanded) -->

  <!-- base_link → link_1: 525mm rise -->
  <joint name="joint_1" type="revolute">
    <origin xyz="0 0 0.525" rpy="0 0 0"/>
    <parent link="base_link"/>
    <child link="link_1"/>
    <axis xyz="0 0 1"/>
    <limit effort="0" lower="-2.9671" upper="2.9671" velocity="3.4034"/>
  </joint>

  <!-- link_1 → link_2: 150mm offset -->
  <joint name="joint_2" type="revolute">
    <origin xyz="0.150 0 0" rpy="0 0 0"/>
    <parent link="link_1"/>
    <child link="link_2"/>
    <axis xyz="0 1 0"/>
    <limit effort="0" lower="-1.7453" upper="2.7925" velocity="3.0543"/>
  </joint>

  <!-- link_2 → link_3: 790mm rise -->
  <joint name="joint_3" type="revolute">
    <origin xyz="0 0 0.790" rpy="0 0 0"/>
    <parent link="link_2"/>
    <child link="link_3"/>
    <axis xyz="0 -1 0"/>
    <limit effort="0" lower="-3.2289" upper="4.7668" velocity="3.1416"/>
  </joint>

  <!-- link_3 → link_4: 250mm rise -->
  <joint name="joint_4" type="revolute">
    <origin xyz="0 0 0.250" rpy="0 0 0"/>
    <parent link="link_3"/>
    <child link="link_4"/>
    <axis xyz="-1 0 0"/>
    <limit effort="0" lower="-3.4907" upper="3.4907" velocity="6.2832"/>
  </joint>

  <!-- link_4 → link_5: 835mm reach -->
  <joint name="joint_5" type="revolute">
    <origin xyz="0.835 0 0" rpy="0 0 0"/>
    <parent link="link_4"/>
    <child link="link_5"/>
    <axis xyz="0 -1 0"/>
    <limit effort="0" lower="-2.4435" upper="2.4435" velocity="6.2832"/>
  </joint>

  <!-- link_5 → link_6: 100mm reach -->
  <joint name="joint_6" type="revolute">
    <origin xyz="0.100 0 0" rpy="0 0 0"/>
    <parent link="link_5"/>
    <child link="link_6"/>
    <axis xyz="-1 0 0"/>
    <limit effort="0" lower="-4.7124" upper="4.7124" velocity="9.5993"/>
  </joint>

</robot>
