<?xml version="1.0"?>
<!--
  FANUC M-710iC/50 URDF
  Generated from: ros-industrial/fanuc fanuc_m710ic50_support/urdf/m710ic50_macro.xacro
  Source: https://github.com/ros-industrial/fanuc
  License: BSD 3-Clause
  Mesh paths resolved to package://fanuc_m710ic50 — maps to /models/fanuc/m710ic50 in the app.
-->
<robot name="fanuc_m710ic50">

  <material name="fanuc_yellow">
    <color rgba="1.0 0.78 0.0 1.0"/>
  </material>
  <material name="fanuc_black">
    <color rgba="0.1 0.1 0.1 1.0"/>
  </material>

  <!-- LINKS -->

  <link name="base_link">
    <visual>
      <origin xyz="0 0 0" rpy="0 0 0"/>
      <geometry>
        <mesh filename="package://fanuc_m710ic50/meshes/visual/base_link.stl"/>
      </geometry>
      <material name="fanuc_black"/>
    </visual>
  </link>

  <link name="link_1">
    <visual>
      <origin xyz="0 0 0" rpy="0 0 0"/>
      <geometry>
        <mesh filename="package://fanuc_m710ic50/meshes/visual/link_1.stl"/>
      </geometry>
      <material name="fanuc_yellow"/>
    </visual>
  </link>

  <link name="link_2">
    <visual>
      <origin xyz="0 0 0" rpy="0 0 0"/>
      <geometry>
        <mesh filename="package://fanuc_m710ic50/meshes/visual/link_2.stl"/>
      </geometry>
      <material name="fanuc_yellow"/>
    </visual>
  </link>

  <link name="link_3">
    <visual>
      <origin xyz="0 0 0" rpy="0 0 0"/>
      <geometry>
        <mesh filename="package://fanuc_m710ic50/meshes/visual/link_3.stl"/>
      </geometry>
      <material name="fanuc_yellow"/>
    </visual>
  </link>

  <link name="link_4">
    <visual>
      <origin xyz="0 0 0" rpy="0 0 0"/>
      <geometry>
        <mesh filename="package://fanuc_m710ic50/meshes/visual/link_4.stl"/>
      </geometry>
      <material name="fanuc_yellow"/>
    </visual>
  </link>

  <link name="link_5">
    <visual>
      <origin xyz="0 0 0" rpy="0 0 0"/>
      <geometry>
        <mesh filename="package://fanuc_m710ic50/meshes/visual/link_5.stl"/>
      </geometry>
      <material name="fanuc_yellow"/>
    </visual>
  </link>

  <link name="link_6">
    <visual>
      <origin xyz="0 0 0" rpy="0 0 0"/>
      <geometry>
        <mesh filename="package://fanuc_m710ic50/meshes/visual/link_6.stl"/>
      </geometry>
      <material name="fanuc_black"/>
    </visual>
  </link>

  <!-- JOINTS (transforms from xacro macro, radians expanded) -->

  <!-- base_link → link_1: 565mm rise -->
  <joint name="joint_1" type="revolute">
    <origin xyz="0 0 0.565" rpy="0 0 0"/>
    <parent link="base_link"/>
    <child link="link_1"/>
    <axis xyz="0 0 1"/>
    <limit effort="0" lower="-3.1415" upper="3.1415" velocity="3.0543"/>
  </joint>

  <!-- link_1 → link_2: 150mm offset -->
  <joint name="joint_2" type="revolute">
    <origin xyz="0.150 0 0" rpy="0 0 0"/>
    <parent link="link_1"/>
    <child link="link_2"/>
    <axis xyz="0 1 0"/>
    <limit effort="0" lower="-1.5707" upper="2.3561" velocity="3.0543"/>
  </joint>

  <!-- link_2 → link_3: 870mm rise -->
  <joint name="joint_3" type="revolute">
    <origin xyz="0 0 0.870" rpy="0 0 0"/>
    <parent link="link_2"/>
    <child link="link_3"/>
    <axis xyz="0 -1 0"/>
    <limit effort="0" lower="-2.7925" upper="4.8869" velocity="3.0543"/>
  </joint>

  <!-- link_3 → link_4: 170mm rise -->
  <joint name="joint_4" type="revolute">
    <origin xyz="0 0 0.170" rpy="0 0 0"/>
    <parent link="link_3"/>
    <child link="link_4"/>
    <axis xyz="-1 0 0"/>
    <limit effort="0" lower="-6.2830" upper="6.2830" velocity="4.3633"/>
  </joint>

  <!-- link_4 → link_5: 1016mm reach -->
  <joint name="joint_5" type="revolute">
    <origin xyz="1.016 0 0" rpy="0 0 0"/>
    <parent link="link_4"/>
    <child link="link_5"/>
    <axis xyz="0 -1 0"/>
    <limit effort="0" lower="-2.1816" upper="2.1816" velocity="4.3633"/>
  </joint>

  <!-- link_5 → link_6: 175mm reach -->
  <joint name="joint_6" type="revolute">
    <origin xyz="0.175 0 0" rpy="0 0 0"/>
    <parent link="link_5"/>
    <child link="link_6"/>
    <axis xyz="-1 0 0"/>
    <limit effort="0" lower="-6.2831" upper="6.2831" velocity="6.1959"/>
  </joint>

</robot>
