<?xml version="1.0"?>
<!--
  ABB CRB 15000 (GoFa) URDF
  Generated from: ros-industrial/abb abb_crb15000_support/urdf/crb15000_macro.xacro
  Source: https://github.com/ros-industrial/abb
  License: BSD 3-Clause
  Mesh paths resolved to package://abb_crb15000 — maps to /models/abb/crb15000 in the app.
-->
<robot name="abb_crb15000">

  <material name="abb_dark_gray">
    <color rgba="0.25 0.25 0.25 1.0"/>
  </material>
  <material name="abb_graphite_white">
    <color rgba="0.85 0.85 0.85 1.0"/>
  </material>
  <material name="abb_gray_white">
    <color rgba="0.7 0.7 0.7 1.0"/>
  </material>

  <!-- LINKS -->

  <link name="base_link">
    <visual>
      <origin xyz="0 0 0" rpy="0 0 0"/>
      <geometry>
        <mesh filename="package://abb_crb15000/meshes/visual/base_link.stl"/>
      </geometry>
      <material name="abb_dark_gray"/>
    </visual>
  </link>

  <link name="link_1">
    <visual>
      <origin xyz="0 0 0" rpy="0 0 0"/>
      <geometry>
        <mesh filename="package://abb_crb15000/meshes/visual/link_1.stl"/>
      </geometry>
      <material name="abb_dark_gray"/>
    </visual>
  </link>

  <link name="link_2">
    <visual>
      <origin xyz="0 0 0" rpy="0 0 0"/>
      <geometry>
        <mesh filename="package://abb_crb15000/meshes/visual/link_2.stl"/>
      </geometry>
      <material name="abb_dark_gray"/>
    </visual>
  </link>

  <link name="link_3">
    <visual>
      <origin xyz="0 0 0" rpy="0 0 0"/>
      <geometry>
        <mesh filename="package://abb_crb15000/meshes/visual/link_3.stl"/>
      </geometry>
      <material name="abb_dark_gray"/>
    </visual>
  </link>

  <link name="link_4">
    <visual>
      <origin xyz="0 0 0" rpy="0 0 0"/>
      <geometry>
        <mesh filename="package://abb_crb15000/meshes/visual/link_4.stl"/>
      </geometry>
      <material name="abb_graphite_white"/>
    </visual>
  </link>

  <link name="link_5">
    <visual>
      <origin xyz="0 0 0" rpy="0 0 0"/>
      <geometry>
        <mesh filename="package://abb_crb15000/meshes/visual/link_5.stl"/>
      </geometry>
      <material name="abb_graphite_white"/>
    </visual>
  </link>

  <link name="link_6">
    <visual>
      <origin xyz="0 0 0" rpy="0 0 0"/>
      <geometry>
        <mesh filename="package://abb_crb15000/meshes/visual/link_6.stl"/>
      </geometry>
      <material name="abb_gray_white"/>
    </visual>
  </link>

  <!-- JOINTS -->

  <!-- base_link → link_1: 265mm rise -->
  <joint name="joint_1" type="revolute">
    <origin rpy="0 0 0" xyz="0 0 0.265"/>
    <parent link="base_link"/>
    <child link="link_1"/>
    <axis xyz="0 0 1"/>
    <limit effort="0" lower="-3.1416" upper="3.1416" velocity="2.1817"/>
  </joint>

  <!-- link_1 → link_2: at origin -->
  <joint name="joint_2" type="revolute">
    <origin rpy="0 0 0" xyz="0 0 0"/>
    <parent link="link_1"/>
    <child link="link_2"/>
    <axis xyz="0 1 0"/>
    <limit effort="0" lower="-3.1416" upper="3.1416" velocity="2.1817"/>
  </joint>

  <!-- link_2 → link_3: 444mm rise -->
  <joint name="joint_3" type="revolute">
    <origin rpy="0 0 0" xyz="0 0 0.444"/>
    <parent link="link_2"/>
    <child link="link_3"/>
    <axis xyz="0 1 0"/>
    <limit effort="0" lower="-3.927" upper="1.484" velocity="2.4435"/>
  </joint>

  <!-- link_3 → link_4: 110mm rise -->
  <joint name="joint_4" type="revolute">
    <origin rpy="0 0 0" xyz="0 0 0.110"/>
    <parent link="link_3"/>
    <child link="link_4"/>
    <axis xyz="1 0 0"/>
    <limit effort="0" lower="-3.1416" upper="3.1416" velocity="3.4907"/>
  </joint>

  <!-- link_4 → link_5: 470mm reach -->
  <joint name="joint_5" type="revolute">
    <origin rpy="0 0 0" xyz="0.470 0 0"/>
    <parent link="link_4"/>
    <child link="link_5"/>
    <axis xyz="0 1 0"/>
    <limit effort="0" lower="-3.1416" upper="3.1416" velocity="3.4907"/>
  </joint>

  <!-- link_5 → link_6: 101mm reach + 80mm rise -->
  <joint name="joint_6" type="revolute">
    <origin rpy="0 0 0" xyz="0.101 0 0.080"/>
    <parent link="link_5"/>
    <child link="link_6"/>
    <axis xyz="1 0 0"/>
    <limit effort="0" lower="-3.1416" upper="3.1416" velocity="3.4907"/>
  </joint>

</robot>
