<?xml version="1.0"?>
<!--
  ABB IRB 1200 URDF
  Generated from: ros-industrial/abb abb_irb1200_support/urdf/irb1200_macro.xacro
  Source: https://github.com/ros-industrial/abb
  License: BSD 3-Clause
  Mesh paths resolved to package://abb_irb1200 — maps to /models/abb/irb1200 in the app.
-->
<robot name="abb_irb1200">

  <material name="abb_orange">
    <color rgba="0.898 0.349 0.024 1.0"/>
  </material>

  <!-- LINKS -->

  <link name="base_link">
    <visual>
      <origin xyz="0 0 0" rpy="0 0 0"/>
      <geometry>
        <mesh filename="package://abb_irb1200/meshes/visual/base_link.stl"/>
      </geometry>
      <material name="abb_orange"/>
    </visual>
  </link>

  <link name="link_1">
    <visual>
      <origin xyz="0 0 0" rpy="0 0 0"/>
      <geometry>
        <mesh filename="package://abb_irb1200/meshes/visual/link_1.stl"/>
      </geometry>
      <material name="abb_orange"/>
    </visual>
  </link>

  <link name="link_2">
    <visual>
      <origin xyz="0 0 0" rpy="0 0 0"/>
      <geometry>
        <mesh filename="package://abb_irb1200/meshes/visual/link_2.stl"/>
      </geometry>
      <material name="abb_orange"/>
    </visual>
  </link>

  <link name="link_3">
    <visual>
      <origin xyz="0 0 0" rpy="0 0 0"/>
      <geometry>
        <mesh filename="package://abb_irb1200/meshes/visual/link_3.stl"/>
      </geometry>
      <material name="abb_orange"/>
    </visual>
  </link>

  <link name="link_4">
    <visual>
      <origin xyz="0 0 0" rpy="0 0 0"/>
      <geometry>
        <mesh filename="package://abb_irb1200/meshes/visual/link_4.stl"/>
      </geometry>
      <material name="abb_orange"/>
    </visual>
  </link>

  <link name="link_5">
    <visual>
      <origin xyz="0 0 0" rpy="0 0 0"/>
      <geometry>
        <mesh filename="package://abb_irb1200/meshes/visual/link_5.stl"/>
      </geometry>
      <material name="abb_orange"/>
    </visual>
  </link>

  <link name="link_6">
    <visual>
      <origin xyz="0 0 0" rpy="0 0 0"/>
      <geometry>
        <mesh filename="package://abb_irb1200/meshes/visual/link_6.stl"/>
      </geometry>
      <material name="abb_orange"/>
    </visual>
  </link>

  <!-- JOINTS -->

  <!-- base_link → link_1: 399.1mm rise -->
  <joint name="joint_1" type="revolute">
    <origin rpy="0 0 0" xyz="0 0 0.3991"/>
    <parent link="base_link"/>
    <child link="link_1"/>
    <axis xyz="0 0 1"/>
    <limit effort="1000" lower="-2.967" upper="2.967" velocity="5.027"/>
  </joint>

  <!-- link_1 → link_2: at origin -->
  <joint name="joint_2" type="revolute">
    <origin rpy="0 0 0" xyz="0 0 0"/>
    <parent link="link_1"/>
    <child link="link_2"/>
    <axis xyz="0 1 0"/>
    <limit effort="1000" lower="-1.745" upper="2.269" velocity="4.189"/>
  </joint>

  <!-- link_2 → link_3: 448mm rise -->
  <joint name="joint_3" type="revolute">
    <origin rpy="0 0 0" xyz="0 0 0.448"/>
    <parent link="link_2"/>
    <child link="link_3"/>
    <axis xyz="0 1 0"/>
    <limit effort="1000" lower="-3.491" upper="1.222" velocity="5.236"/>
  </joint>

  <!-- link_3 → link_4: 42mm rise -->
  <joint name="joint_4" type="revolute">
    <origin rpy="0 0 0" xyz="0 0 0.042"/>
    <parent link="link_3"/>
    <child link="link_4"/>
    <axis xyz="1 0 0"/>
    <limit effort="1000" lower="-4.712" upper="4.712" velocity="6.981"/>
  </joint>

  <!-- link_4 → link_5: 451mm reach -->
  <joint name="joint_5" type="revolute">
    <origin rpy="0 0 0" xyz="0.451 0 0"/>
    <parent link="link_4"/>
    <child link="link_5"/>
    <axis xyz="0 1 0"/>
    <limit effort="1000" lower="-2.269" upper="2.269" velocity="7.069"/>
  </joint>

  <!-- link_5 → link_6: 82mm reach -->
  <joint name="joint_6" type="revolute">
    <origin rpy="0 0 0" xyz="0.082 0 0"/>
    <parent link="link_5"/>
    <child link="link_6"/>
    <axis xyz="1 0 0"/>
    <limit effort="1000" lower="-6.283" upper="6.283" velocity="10.472"/>
  </joint>

</robot>
